Workbook
Name Slicer_Įmonės_pavadinimas: #N/A
Name Slicer_Metai: #N/A
Name Slicer_Pagrindinis_brandas: #N/A
Name Slicer_Veikla__BTL: #N/A
Name Slicer_Veikla__BTL1: #N/A
Name Slicer_Veikla__Digital_media: #N/A
Name Slicer_Veikla__Digital_media1: #N/A
Name Slicer_Veikla__Konsultantai: #N/A
Name Slicer_Veikla__Konsultantai1: #N/A
Name Slicer_Veikla__kūryba: #N/A
Name Slicer_Veikla__kūryba1: #N/A
Name Slicer_Veikla__Media: #N/A
Name Slicer_Veikla__Media1: #N/A
Name Slicer_Veikla__PA: #N/A
Name Slicer_Veikla__PA1: #N/A
Name Slicer_Veikla__PR: #N/A
Name Slicer_Veikla__PR1: #N/A
Name Slicer_Veikla__Production_house: #N/A
Name Slicer_Veikla__Production_house1: #N/A
Name Slicer_Veikla__renginiai: #N/A
Name Slicer_Veikla__Renginiai1: #N/A

Sheet Raw
A1: Preliminarus pavadinimas | B1: Preliminari svetainė | C1: EVRK v2 veiklos kodas | D1: EVRK v2 veikla | E1: Column3 | F1: Veikla | G1: Column1 | H1: Column2 | I1: Kodas | J1: PVM kodas | K1: Įmonė | L1: Adresas | M1: Miestas | N1: El. paštas | O1: Telefonas | P1: Mobilus | Q1: Kiti telefonai | R1: Darbuotojai 2019 | S1: Darbuotojai 2020 | T1: Darb. Pokytis 19-20 | U1: Darbuotojai 2021 | V1: Darb. Pokytis 20-21 | W1: Darbuotojai 2022 | X1: Darb. Pokytis 21-22 | Y1: Darbuotojai 2023 | Z1: Darb. Pokytis 22-23 | AA1: Darbuotojai 2024 | AB1: Darb. Pokytis 23-24 | AC1: Darbuotojai 2025 06 09 | AD1: Atlyginimų vidurkis 2019 | AE1: Atlyginimų vidurkis 2020 | AF1: Atl .Pokytis 19-20 | AG1: Atlyginimų vidurkis 2021 | AH1: Atl. Pokytis 20-21 | AI1: Atlyginimų vidurkis 2022 | AJ1: Atl. Pokytis 21-22 | AK1: Atlyginimų vidurkis 2023 | AL1: Atl. Pokytis 22-23 | AM1: Atlyginimų vidurkis 2024 | AN1: Atl. Pokytis 23-24 | AO1: Atlyginimų vidurkis 2025 04 | AP1: Skola Sodrai | AQ1: Apyvarta 2019 | AR1: Apyvarta 2020 | AS1: Apyvart. Pokytis 19-20 | AT1: Apyvarta 2021 | AU1: Apyvart. Pokytis 20-21 | AV1: Apyvarta 2022 | AW1: Apyvart. Pokytis 21-22 | AX1: Apyvarta 2023 | AY1: Apyvart. Pokytis 22-23 | AZ1: Apyvarta 2024 | BA1: Apyvart. Pokytis 23-24 | BB1: Grynasis pelnas 2019 | BC1: Grynasis pelnas 2020 | BD1: Gr. Peln. Pokytis 19-20 | BE1: Grynasis pelnas 2021 | BF1: Gr. Peln. Pokytis 20-21 | BG1: Grynasis pelnas 2022 | BH1: Gr. Peln. Pokytis 21-22 | BI1: Grynasis pelnas 2023 | BJ1: Gr. Peln. Pokytis 22-23 | BK1: Grynasis pelnas 2024 | BL1: Gr. Peln. Pokytis 23-24 | BM1: Svetainė | BN1: Rekvizitai URL | BO1: Facebook | BP1: Instagram | BQ1: LinkedIn | BR1: Kredito rizika | BS1: Įregistruota
A2: Dentsu Lithuania, UAB | B2: dentsu.lt | C2: 731100 | D2: Media | I2: 124216438 | J2: LT242164314 | K2: Dentsu Lithuania UAB | L2: A. Goštauto g. 40B, LT-03163 Vilnius | M2: Vilnius | N2: info.lithuania@dentsu.com | O2: +370 5 2497241 | R2: 18 | S2: 18 | T2: 0 | U2: 19 | V2: 0.055555556 | W2: 63 | X2: 2.3157895 | Y2: 68 | Z2: 0.079365079 | AA2: 63 | AB2: -0.073529412 | AC2: 53 | AD2: 3220 | AE2: 3348 | AF2: 0.039751553 | AG2: 3357 | AH2: 0.002688172 | AI2: 3112 | AJ2: -0.072981829 | AK2: 3397 | AL2: 0.091580977 | AM2: 3711 | AN2: 0.092434501 | AO2: 3723,40 | AQ2: 8897302 | AR2: 8847434 | AS2: -0.0056048452 | AT2: 8730690 | AU2: -0.013195238 | AV2: 29179075 | AW2: 2.342127 | AX2: 31485566 | AY2: 0.079046063 | AZ2: 36638811 | BA2: 0.16367008 | BB2: 160646 | BC2: 246272 | BD2: 0.53301047 | BE2: 111387 | BF2: -0.54770741 | BG2: 395590 | BH2: 2.5514916 | BI2: 504281 | BJ2: 0.27475669 | BK2: 1889619 | BL2: 2.7471549 | BM2: https://www.dentsu.com/ | BN2: https://rekvizitai.vz.lt/imone/dentsu_lithuania/ | BO2: https://www.facebook.com/Dentsu-Lithuania-111642568134310 | BR2: Žemiausia | BS2: 1997-10-16
A3: Inspired Communications, UAB | B3: inspired.lt | C3: 731100 | D3: Media | I3: 300642933 | J3: LT100002908017 | K3: UAB "Inspired Communications" | L3: Paupio g. 16, LT-11341 Vilnius | M3: Vilnius | N3: office@inspired.lt | O3: +370 684 65990 | P3: 37068465990 | R3: 49 | S3: 47 | T3: -0.040816327 | U3: 51 | V3: 0.085106383 | W3: 40 | X3: -0.21568627 | Y3: 32 | Z3: -0.2 | AA3: 31 | AB3: -0.03125 | AC3: 31 | AD3: 2418 | AE3: 2300 | AF3: -0.048800662 | AG3: 2604 | AH3: 0.13217391 | AI3: 2988 | AJ3: 0.14746544 | AK3: 3726 | AL3: 0.24698795 | AM3: 4330 | AN3: 0.16210413 | AO3: 4103,94 | AQ3: 19167730 | AR3: 20518557 | AS3: 0.070474021 | AT3: 19713947 | AU3: -0.039213771 | AV3: 17453957 | AW3: -0.11463914 | AX3: 26945192 | AY3: 0.543787 | AZ3: 21601990 | BA3: -0.1982989 | BB3: 703603 | BC3: 711078 | BD3: 0.010623889 | BE3: 601013 | BF3: -0.15478611 | BG3: 490845 | BH3: -0.18330386 | BI3: 658350 | BJ3: 0.34125844 | BK3: 294872 | BL3: -0.5521045 | BM3: http://www.inspired.lt | BN3: https://rekvizitai.vz.lt/imone/inspired_communications/ | BO3: https://www.facebook.com/inspired.lab | BQ3: https://www.linkedin.com/company/inspired-um | BR3: Žemiausia | BS3: 2007-02-05
A4: Open Agency, UAB | B4: openagency.lt | C4: 731100 | D4: Media | I4: 302414298 | J4: LT100004786814 | K4: UAB "Open Agency" | L4: A. Goštauto g. 40, LT-03163 Vilnius | M4: Vilnius | N4: open@openagency.lt | O4: +370 5 2195252 | R4: 43 | S4: 46 | T4: 0.069767442 | U4: 49 | V4: 0.065217391 | W4: 53 | X4: 0.081632653 | Y4: 52 | Z4: -0.018867925 | AA4: 53 | AB4: 0.019230769 | AC4: 54 | AD4: 2178 | AE4: 2052 | AF4: -0.05785124 | AG4: 2453 | AH4: 0.1954191 | AI4: 2626 | AJ4: 0.070525887 | AK4: 2583 | AL4: -0.016374714 | AM4: 2644 | AN4: 0.02361595 | AO4: 2816,67 | AQ4: 14735922 | AR4: 13065559 | AS4: -0.11335314 | AT4: 16083759 | AU4: 0.23100428 | AV4: 15673573 | AW4: -0.025503118 | AX4: 15193407 | AY4: -0.030635389 | AZ4: 16809406 | BA4: 0.10636186 | BB4: 447413 | BC4: 426889 | BD4: -0.045872605 | BE4: 501734 | BF4: 0.17532661 | BG4: 441594 | BH4: -0.11986431 | BI4: 411549 | BJ4: -0.068037609 | BK4: 478689 | BL4: 0.16313975 | BM4: http://www.openagency.lt | BN4: https://rekvizitai.vz.lt/imone/open_agency/ | BR4: Žemiausia | BS4: 2009-07-01
A5: Media House, UAB | B5: mediahouse.lt | C5: 731200 | D5: Media | I5: 111707070 | J5: LT117070716 | K5: Uždaroji akcinė bendrovė "MEDIA HOUSE" | L5: Aukštaičių g. 7, LT-11341 Vilnius | M5: Vilnius | N5: contact@media-house.com | O5: +370 5 2526270 | R5: 34 | S5: 30 | T5: -0.11764706 | U5: 30 | V5: 0 | W5: 36 | X5: 0.2 | Y5: 36 | Z5: 0 | AA5: 35 | AB5: -0.027777778 | AC5: 39 | AD5: 2463 | AE5: 2559 | AF5: 0.038976857 | AG5: 2700 | AH5: 0.055099648 | AI5: 2844 | AJ5: 0.053333333 | AK5: 3103 | AL5: 0.091068917 | AM5: 3298 | AN5: 0.062842411 | AO5: 3468,10 | AQ5: 10898125 | AR5: 11162492 | AS5: 0.024258026 | AT5: 13680319 | AU5: 0.22556137 | AV5: 14993931 | AW5: 0.09602203 | AX5: 19737855 | AY5: 0.31638961 | AZ5: 15451756 | BA5: -0.21715121 | BB5: 203683 | BC5: 307350 | BD5: 0.50896246 | BE5: 391733 | BF5: 0.27455019 | BG5: 294380 | BH5: -0.24851876 | BI5: 385809 | BJ5: 0.31058156 | BK5: 244146 | BL5: -0.36718428 | BM5: http://media-house.com/ | BN5: https://rekvizitai.vz.lt/imone/media_house/ | BO5: https://www.facebook.com/MediaHouseLT | BR5: Žemiausia | BS5: 2000-07-27
A6: Whatabout.agency, UAB | B6: whatabout.agency | C6: 631200 | D6: Interneto vartų paslaugų veikla | I6: 302795358 | J6: LT100008130318 | K6: Whatabout agency, UAB | L6: Laisvės al. 59, Kaunas | M6: Kaunas | N6: info@whatabout.agency | O6: +370 610 79316 | R6: 17 | S6: 20 | T6: 0.17647059 | U6: 21 | V6: 0.05 | W6: 30 | X6: 0.42857143 | Y6: 35 | Z6: 0.16666667 | AA6: 36 | AB6: 0.028571429 | AC6: 32 | AD6: 972 | AE6: 1273 | AF6: 0.30967078 | AG6: 1535 | AH6: 0.20581304 | AI6: 1938 | AJ6: 0.26254072 | AK6: 2374 | AL6: 0.2249742 | AM6: 2497 | AN6: 0.051811289 | AO6: 2646,03 | AQ6: 1140388 | AR6: 1946452 | AS6: 0.70683311 | AT6: 6988301 | AU6: 2.5902766 | AV6: 7033233 | AW6: 0.0064296028 | AX6: 8766185 | AY6: 0.24639479 | AZ6: 11931673 | BA6: 0.36110212 | BB6: 100333 | BC6: 123598 | BD6: 0.23187785 | BE6: 143302 | BF6: 0.15942006 | BG6: -85287 | BH6: -1.5951557 | BI6: 49952 | BJ6: 1.585693 | BK6: -382931 | BL6: -8.6659793 | BM6: https://whatabout.agency/ | BN6: https://rekvizitai.vz.lt/imone/whatabout_agency/ | BO6: https://www.facebook.com/whatabout.lt | BP6: https://www.instagram.com/whatabout.agency/ | BQ6: https://www.linkedin.com/company/whatabout/ | BR6: Žema | BS6: 2012-06-04
A7: Reprise Media, UAB | B7: reprise.com | C7: 731100 | G7: Digital media | I7: 304737161 | J7: LT100011362012 | K7: UAB "Reprise Media" | L7: Šaltinių g. 12, LT-03214 Vilnius | M7: Vilnius | N7: info@reprise.lt | P7: 37068465990 | Q7: +370 613 75088 | R7: 17 | S7: 21 | T7: 0.23529412 | U7: 27 | V7: 0.28571429 | W7: 30 | X7: 0.11111111 | Y7: 29 | Z7: -0.033333333 | AA7: 25 | AB7: -0.13793103 | AC7: 25 | AD7: 2233 | AE7: 2199 | AF7: -0.015226153 | AG7: 2483 | AH7: 0.12914961 | AI7: 2808 | AJ7: 0.13089005 | AK7: 3307 | AL7: 0.17770655 | AM7: 3578 | AN7: 0.081947384 | AO7: 4181,84 | AQ7: 3984255 | AR7: 5638018 | AS7: 0.41507459 | AT7: 7175635 | AU7: 0.27272297 | AV7: 11433659 | AW7: 0.59340031 | AX7: 19745738 | AY7: 0.72698329 | AZ7: 11526712 | BA7: -0.41624304 | BB7: 211408 | BC7: 565438 | BD7: 1.6746292 | BE7: 468860 | BF7: -0.1708021 | BG7: 587419 | BH7: 0.25286653 | BI7: 345373 | BJ7: -0.41205 | BK7: 95363 | BL7: -0.72388403 | BM7: https://reprise.lt/ | BN7: https://rekvizitai.vz.lt/imone/reprise_media/ | BR7: Žemiausia | BS7: 2017-12-18
A8: Arena Media, UAB | B8: arenamedia.lt | C8: 731100 | D8: Media | I8: 300597228 | J8: LT100002645214 | K8: Arena Media, UAB | L8: Jogailos g. 4, LT-01116 Vilnius | M8: Vilnius | N8: media@arenamedia.lt | O8: +370 5 2690033 | R8: 16 | S8: 11 | T8: -0.3125 | U8: 12 | V8: 0.090909091 | W8: 13 | X8: 0.083333333 | Y8: 14 | Z8: 0.076923077 | AA8: 14 | AB8: 0 | AC8: 13 | AD8: 2374 | AE8: 2606 | AF8: 0.097725358 | AG8: 3065 | AH8: 0.176132 | AI8: 3304 | AJ8: 0.077977162 | AK8: 3252 | AL8: -0.015738499 | AM8: 3314 | AN8: 0.019065191 | AO8: 3423,28 | AQ8: 8490273 | AR8: 8162394 | AS8: -0.038618193 | AT8: 13416624 | AU8: 0.64371188 | AV8: 14637212 | AW8: 0.090975792 | AX8: 13076706 | AY8: -0.10661224 | AZ8: 10772482 | BA8: -0.17620829 | BB8: 385151 | BC8: 357029 | BD8: -0.073015519 | BE8: 351536 | BF8: -0.015385305 | BG8: 480070 | BH8: 0.36563538 | BI8: 376803 | BJ8: -0.21510821 | BK8: 78192 | BL8: -0.79248573 | BM8: http://www.arenamedia.lt | BN8: https://rekvizitai.vz.lt/imone/adcom/ | BR8: Žemiausia | BS8: 2006-09-08
A9: Havas Media, UAB | B9: havasmedia.lt | C9: 731100 | D9: Media | I9: 302344394 | J9: LT100004728312 | K9: Havas Media, UAB | L9: Jogailos g. 4, LT-01116 Vilnius | M9: Vilnius | N9: info@havasmedia.lt | O9: +370 616 76777 | R9: 21 | S9: 19 | T9: -0.095238095 | U9: 20 | V9: 0.052631579 | W9: 22 | X9: 0.1 | Y9: 22 | Z9: 0 | AA9: 24 | AB9: 0.090909091 | AC9: 22 | AD9: 2194 | AE9: 2559 | AF9: 0.16636281 | AG9: 2794 | AH9: 0.091832747 | AI9: 2988 | AJ9: 0.069434503 | AK9: 3492 | AL9: 0.1686747 | AM9: 3663 | AN9: 0.048969072 | AO9: 4774,82 | AQ9: 7511674 | AR9: 8107694 | AS9: 0.079345829 | AT9: 9433509 | AU9: 0.16352554 | AV9: 9608231 | AW9: 0.018521422 | AX9: 10925676 | AY9: 0.13711629 | AZ9: 10632287 | BA9: -0.026853167 | BB9: 301781 | BC9: 278089 | BD9: -0.078507262 | BE9: 322559 | BF9: 0.15991283 | BG9: 134980 | BH9: -0.58153392 | BI9: 123945 | BJ9: -0.081752852 | BK9: 248039 | BL9: 1.0012021 | BN9: https://rekvizitai.vz.lt/imone/uab_mpg_idea/ | BR9: Žemiausia | BS9: 2009-05-28
A10: Via Media, UAB | B10: viamedia.lt | C10: 731100 | D10: Media | I10: 111625698 | J10: LT116256917 | K10: Uždaroji akcinė bendrovė "VIA MEDIA" | L10: Aukštaičių g. 7, LT-11341 Vilnius | M10: Vilnius | N10: office.lithuania@mindsharebaltics.com | P10: 37061794865 | R10: 19 | S10: 18 | T10: -0.052631579 | U10: 24 | V10: 0.33333333 | W10: 28 | X10: 0.16666667 | Y10: 26 | Z10: -0.071428571 | AA10: 25 | AB10: -0.038461538 | AC10: 27 | AD10: 2532 | AE10: 2641 | AF10: 0.043048973 | AG10: 2528 | AH10: -0.042786823 | AI10: 2626 | AJ10: 0.038765823 | AK10: 2861 | AL10: 0.089489718 | AM10: 3073 | AN10: 0.074099965 | AO10: 3024,69 | AQ10: 6233775 | AR10: 4829619 | AS10: -0.22524971 | AT10: 9494507 | AU10: 0.96589151 | AV10: 10013897 | AW10: 0.054704262 | AX10: 8389454 | AY10: -0.16221886 | AZ10: 8837519 | BA10: 0.053408124 | BB10: 112253 | BC10: 95358 | BD10: -0.15050823 | BE10: 191943 | BF10: 1.0128673 | BG10: 186159 | BH10: -0.030133946 | BI10: 172710 | BJ10: -0.072244694 | BK10: 225361 | BL10: 0.30485206 | BM10: https://www.mindshareworld.com/lithuania/offices/vilnius-lithuania | BN10: https://rekvizitai.vz.lt/imone/via_media/ | BR10: Žema | BS10: 1998-03-31
A11: Trendmark, UAB | B11: trendmark.lt | C11: 731200 | D11: Media | I11: 300021385 | J11: LT100001028614 | K11: UAB "Trendmark" | L11: Savičiaus g. 3A-36, LT-01127 Vilnius | M11: Vilnius | N11: info@mediacom.lt | O11: +370 5 2608463 | R11: 21 | S11: 20 | T11: -0.047619048 | U11: 19 | V11: -0.05 | W11: 20 | X11: 0.052631579 | Y11: 20 | Z11: 0 | AA11: 24 | AB11: 0.2 | AC11: 23 | AD11: 2175 | AE11: 2572 | AF11: 0.18252874 | AG11: 2688 | AH11: 0.045101089 | AI11: 2915 | AJ11: 0.084449405 | AK11: 3033 | AL11: 0.040480274 | AM11: 2672 | AN11: -0.11902407 | AO11: 2653,34 | AQ11: 6385159 | AR11: 5903710 | AS11: -0.075401255 | AT11: 7141593 | AU11: 0.20967883 | AV11: 7598409 | AW11: 0.063965561 | AX11: 7543028 | AY11: -0.0072884995 | AZ11: 8271381 | BA11: 0.096559764 | BB11: 57099 | BC11: 242860 | BD11: 3.2533144 | BE11: 340088 | BF11: 0.40034588 | BG11: 99335 | BH11: -0.70791383 | BI11: 66752 | BJ11: -0.32801127 | BK11: 131476 | BL11: 0.96961889 | BM11: http://www.mediacom.lt | BN11: https://rekvizitai.vz.lt/imone/trendmark/ | BR11: Žemiausia | BS11: 2004-04-27
A12: Adell reklama, UAB | C12: 731100 | E12: Kūryba | I12: 110771682 | J12: LT107716811 | K12: Uždaroji akcinė bendrovė "ADELL REKLAMA" | L12: Aukštaičių g. 7u, LT-11341 Vilnius | M12: Vilnius | N12: david@ogilvy.lt | O12: +370 619 19525 | R12: 45 | S12: 46 | T12: 0.022222222 | U12: 50 | V12: 0.086956522 | W12: 49 | X12: -0.02 | Y12: 49 | Z12: 0 | AA12: 45 | AB12: -0.081632653 | AC12: 43 | AD12: 2709 | AE12: 2940 | AF12: 0.085271318 | AG12: 3106 | AH12: 0.056462585 | AI12: 3263 | AJ12: 0.050547328 | AK12: 4041 | AL12: 0.23843089 | AM12: 3618 | AN12: -0.10467706 | AO12: 3183,97 | AQ12: 7290500 | AR12: 6554110 | AS12: -0.10100679 | AT12: 7010847 | AU12: 0.069687112 | AV12: 8435901 | AW12: 0.20326417 | AX12: 7661419 | AY12: -0.091807858 | AZ12: 7456879 | BA12: -0.026697404 | BB12: 638469 | BC12: 637044 | BD12: -0.0022319016 | BE12: 689700 | BF12: 0.082656771 | BG12: 1148871 | BH12: 0.66575468 | BI12: 625927 | BJ12: -0.45518078 | BK12: 493389 | BL12: -0.21174674 | BM12: http://www.ogilvy.lt | BN12: https://rekvizitai.vz.lt/imone/adell_reklama/ | BR12: Žemiausia | BS12: 1997-04-18
A13: Fabula ir partneriai, UAB | B13: fabula.lt | C13: 702100 | E13: Kūryba | F13: PR | G13: Digital media | H13: PA | I13: 124099127 | J13: LT240991219 | K13: UAB "Fabula ir partneriai" | L13: Gedimino pr. 10-5, Vilnius | M13: Vilnius | N13: info@fabula.lt | P13: 37065631548 | R13: 37 | S13: 34 | T13: -0.081081081 | U13: 40 | V13: 0.17647059 | W13: 40 | X13: 0 | Y13: 42 | Z13: 0.05 | AA13: 44 | AB13: 0.047619048 | AC13: 39 | AD13: 2524 | AE13: 2480 | AF13: -0.017432647 | AG13: 2666 | AH13: 0.075 | AI13: 2813 | AJ13: 0.055138785 | AK13: 3112 | AL13: 0.10629221 | AM13: 3463 | AN13: 0.1127892 | AO13: 3525,44 | AQ13: 2788993 | AR13: 2555815 | AS13: -0.08360652 | AT13: 3502499 | AU13: 0.37040396 | AV13: 3936974 | AW13: 0.12404714 | AX13: 4517735 | AY13: 0.14751456 | AZ13: 5231622 | BA13: 0.15801879 | BB13: 193716 | BC13: 246631 | BD13: 0.27315761 | BE13: 294912 | BF13: 0.19576209 | BG13: 269786 | BH13: -0.085198296 | BI13: 316849 | BJ13: 0.17444567 | BK13: 329162 | BL13: 0.038860782 | BM13: http://www.fabula.lt | BN13: https://rekvizitai.vz.lt/imone/viesuju_rysiu_partneriai/ | BR13: Žemiausia | BS13: 1997-07-03
A14: SOMA Agency (Havas), UAB | B14: somaagency.lt | C14: 731100 | E14: kūryba | G14: Digital media | I14: 302713051 | J14: LT100006633414 | K14: Havas Creative SOMA, UAB | L14: Jogailos g. 4, LT-01116 Vilnius | M14: Vilnius | N14: info@soma.agency | P14: 37061676777 | R14: 28 | S14: 26 | T14: -0.071428571 | U14: 30 | V14: 0.15384615 | W14: 43 | X14: 0.43333333 | Y14: 40 | Z14: -0.069767442 | AA14: 43 | AB14: 0.075 | AC14: 35 | AD14: 1923 | AE14: 2084 | AF14: 0.083723349 | AG14: 2229 | AH14: 0.069577735 | AI14: 2748 | AJ14: 0.23283984 | AK14: 3185 | AL14: 0.15902475 | AM14: 3281 | AN14: 0.030141287 | AO14: 3350,62 | AQ14: 2542792 | AR14: 2699328 | AS14: 0.061560678 | AT14: 3544935 | AU14: 0.31326575 | AV14: 5294859 | AW14: 0.49364065 | AX14: 5094797 | AY14: -0.037784198 | AZ14: 5026701 | BA14: -0.013365793 | BB14: 229725 | BC14: 38351 | BD14: -0.83305692 | BE14: 230336 | BF14: 5.0059972 | BG14: 140814 | BH14: -0.38865831 | BI14: 80642 | BJ14: -0.42731547 | BK14: -152937 | BL14: -2.8964931 | BN14: https://rekvizitai.vz.lt/imone/socialus_marketingas/ | BR14: Žemiausia | BS14: 2012-01-17
A15: Partizanas, UAB | B15: partizanas.lt | C15: 731100 | D15: renginiai | I15: 300065271 | J15: LT100001307515 | K15: Uždaroji akcinė bendrovė "PARTIZANAS" | L15: Kauno g. 16-303, LT-03212 Vilnius | M15: Vilnius | N15: info@partizanas.lt | O15: +370 5 2335527 | R15: 36 | S15: 44 | T15: 0.22222222 | U15: 99 | V15: 1.25 | W15: 82 | X15: -0.17171717 | Y15: 78 | Z15: -0.048780488 | AA15: 31 | AB15: -0.6025641 | AC15: 36 | AD15: 1280 | AE15: 1412 | AF15: 0.103125 | AG15: 1650 | AH15: 0.16855524 | AI15: 2101 | AJ15: 0.27333333 | AK15: 2396 | AL15: 0.14040933 | AM15: 2591 | AN15: 0.081385643 | AO15: 2759,13 | AQ15: 3066953 | AR15: 1961813 | AS15: -0.36033809 | AT15: 3042658 | AU15: 0.55094191 | AV15: 4774281 | AW15: 0.56911523 | AX15: 5838294 | AY15: 0.22286351 | AZ15: 4789830 | BA15: -0.17958397 | BB15: 212789 | BC15: 132198 | BD15: -0.37873668 | BE15: 219867 | BF15: 0.66316434 | BG15: 318475 | BH15: 0.44848931 | BI15: 365605 | BJ15: 0.1479865 | BK15: 132820 | BL15: -0.63671175 | BM15: http://www.partizanas.lt | BN15: https://rekvizitai.vz.lt/imone/partizanas/ | BR15: Žemiausia | BS15: 2004-11-04
A16: Publicum, UAB | B16: publicum.lt | C16: 702100 | F16: pr | I16: 125671759 | J16: LT256717515 | K16: UŽDAROJI AKCINĖ BENDROVĖ "PUBLICUM" | L16: Jogailos g. 4, LT-01116 Vilnius | M16: Vilnius | N16: info@publicum.lt | P16: 37061125839 | R16: 20 | S16: 20 | T16: 0 | U16: 22 | V16: 0.1 | W16: 25 | X16: 0.13636364 | Y16: 26 | Z16: 0.04 | AA16: 24 | AB16: -0.076923077 | AC16: 22 | AD16: 2883 | AE16: 3361 | AF16: 0.16579951 | AG16: 3888 | AH16: 0.15679857 | AI16: 3765 | AJ16: -0.031635802 | AK16: 4390 | AL16: 0.16600266 | AM16: 4929 | AN16: 0.12277904 | AO16: 4917,04 | AQ16: 3590407 | AR16: 3042886 | AS16: -0.15249552 | AT16: 4312296 | AU16: 0.41717304 | AV16: 4312150 | AW16: -3.3856674e-05 | AX16: 4315944 | AY16: 0.00087983952 | AZ16: 4743413 | BA16: 0.099044149 | BB16: 678081 | BC16: 361920 | BD16: -0.46625846 | BE16: 728377 | BF16: 1.0125359 | BG16: 759242 | BH16: 0.042375034 | BI16: 828689 | BJ16: 0.09146886 | BK16: 684359 | BL16: -0.17416667 | BM16: http://www.publicum.lt | BN16: https://rekvizitai.vz.lt/imone/publicum/ | BR16: Žemiausia | BS16: 2001-06-29
A17: SuperYou, UAB | B17: superyou.lt | C17: 731100 | G17: Digital media | I17: 302705193 | J17: LT100007489513 | K17: UAB "SuperYou" | L17: Švitrigailos g. 11B, Vilnius | M17: Vilnius | N17: superyou@superyou.lt | P17: 37068646164 | R17: 16 | S17: 27 | T17: 0.6875 | U17: 41 | V17: 0.51851852 | W17: 52 | X17: 0.26829268 | Y17: 56 | Z17: 0.076923077 | AA17: 50 | AB17: -0.10714286 | AC17: 41 | AD17: 2194 | AE17: 2182 | AF17: -0.0054694622 | AG17: 2407 | AH17: 0.10311641 | AI17: 2574 | AJ17: 0.069380972 | AK17: 2787 | AL17: 0.082750583 | AM17: 3005 | AN17: 0.078220309 | AO17: 3057,22 | AQ17: 1161676 | AR17: 1881602 | AS17: 0.61973046 | AT17: 2745328 | AU17: 0.45903756 | AV17: 3189523 | AW17: 0.16180034 | AX17: 3156815 | AY17: -0.010254825 | AZ17: 3457966 | BA17: 0.095397101 | BB17: 15451 | BC17: 76484 | BD17: 3.9501003 | BE17: 28066 | BF17: -0.63304743 | BG17: 44871 | BH17: 0.59876719 | BI17: 8499 | BJ17: -0.81059036 | BK17: 10004 | BL17: 0.17707966 | BM17: http://www.superyou.lt | BN17: https://rekvizitai.vz.lt/imone/the_xx/ | BR17: Žema | BS17: 2011-12-30
A18: co:agency, UAB | B18: coagency.lt | C18: 702200 | F18: pr | I18: 300078393 | J18: LT100001552013 | K18: UAB coagency | L18: Paupio g. 50-136, LT-11341 Vilnius | M18: Vilnius | N18: info@coagency.lt | P18: 37065559478 | R18: 21 | S18: 21 | T18: 0 | U18: 26 | V18: 0.23809524 | W18: 27 | X18: 0.038461538 | Y18: 26 | Z18: -0.037037037 | AA18: 24 | AB18: -0.076923077 | AC18: 33 | AD18: 1975 | AE18: 1912 | AF18: -0.031898734 | AG18: 2050 | AH18: 0.072175732 | AI18: 2306 | AJ18: 0.12487805 | AK18: 2557 | AL18: 0.10884649 | AM18: 2745 | AN18: 0.073523661 | AO18: 2984,40 | AQ18: 2883332 | AR18: 2684538 | AS18: -0.068945928 | AT18: 3293875 | AU18: 0.22698021 | AV18: 3529291 | AW18: 0.071470836 | AX18: 4148973 | AY18: 0.17558257 | AZ18: 3374832 | BA18: -0.18658617 | BB18: 94625 | BC18: 205039 | BD18: 1.1668587 | BE18: 219463 | BF18: 0.070347592 | BG18: 281973 | BH18: 0.28483161 | BI18: 220705 | BJ18: -0.21728322 | BK18: 281779 | BL18: 0.27672232 | BM18: http://www.coagency.lt | BN18: https://rekvizitai.vz.lt/imone/coagency/ | BR18: Žemiausia | BS18: 2005-01-06
A19: NEW! Creative Agency, UAB | B19: newcreative.lt | C19: 731100 | E19: Kūryba | I19: 302704981 | J19: LT100006600519 | K19: UAB "New Agency" | L19: A. Goštauto g. 40-1, Vilnius | M19: Vilnius | N19: goodnews@newisnew.lt | P19: 37060870533 | R19: 16 | S19: 19 | T19: 0.1875 | U19: 23 | V19: 0.21052632 | W19: 26 | X19: 0.13043478 | Y19: 27 | Z19: 0.038461538 | AA19: 25 | AB19: -0.074074074 | AC19: 19 | AD19: 1952 | AE19: 1803 | AF19: -0.076331967 | AG19: 1970 | AH19: 0.092623405 | AI19: 2512 | AJ19: 0.2751269 | AK19: 2995 | AL19: 0.19227707 | AM19: 3105 | AN19: 0.03672788 | AO19: 3428,82 | AQ19: 1642462 | AR19: 2170995 | AS19: 0.32179314 | AT19: 2012184 | AU19: -0.073151251 | AV19: 2854292 | AW19: 0.41850447 | AX19: 3034911 | AY19: 0.063279791 | AZ19: 3272793 | BA19: 0.07838187 | BB19: 5768 | BC19: 4980 | BD19: -0.13661581 | BE19: -93219 | BF19: -19.718675 | BG19: 68130 | BH19: 1.7308596 | BI19: -30674 | BJ19: -1.4502275 | BK19: 30560 | BL19: 1.9962835 | BM19: http://www.newisnew.lt | BN19: https://rekvizitai.vz.lt/imone/new_agency/ | BO19: https://www.facebook.com/NewCreativeAgency/ | BR19: Žema | BS19: 2011-12-30
A20: Not Perfect, UAB | B20: notperfect.lt | C20: 731100 | E20: Kūryba | I20: 300529266 | J20: LT100002437412 | K20: UAB "Not Perfect Vilnius" | L20: Antakalnio g. 17, LT-10312 Vilnius | M20: Vilnius | N20: vilnius@notperfect.com | P20: 37067344446 | R20: 13 | S20: 18 | T20: 0.38461538 | U20: 30 | V20: 0.66666667 | W20: 35 | X20: 0.16666667 | Y20: 37 | Z20: 0.057142857 | AA20: 35 | AB20: -0.054054054 | AC20: 31 | AD20: 1427 | AE20: 1617 | AF20: 0.13314646 | AG20: 2218 | AH20: 0.37167594 | AI20: 2630 | AJ20: 0.18575293 | AK20: 3213 | AL20: 0.221673 | AM20: 3248 | AN20: 0.010893246 | AO20: 2844,20 | AQ20: 2461430 | AR20: 2095356 | AS20: -0.14872412 | AT20: 3406485 | AU20: 0.6257309 | AV20: 3253190 | AW20: -0.045000932 | AX20: 4214370 | AY20: 0.29545769 | AZ20: 3158150 | BA20: -0.25062346 | BB20: 118464 | BC20: 102345 | BD20: -0.13606665 | BE20: 225233 | BF20: 1.200723 | BG20: 130725 | BH20: -0.41960104 | BI20: 50994 | BJ20: -0.60991394 | BK20: -73517 | BL20: -2.4416794 | BM20: http://www.notperfect.com/ | BN20: https://rekvizitai.vz.lt/imone/not_perfect/ | BR20: Žemiausia | BS20: 2006-01-24
A21: Idea Prima, UAB | B21: ideaprima.lt | C21: 702100 | F21: PR | I21: 126093354 | J21: LT260933515 | K21: UAB "Idea prima" | L21: Pylimo g. 58, LT-01307 Vilnius | M21: Vilnius | N21: info@ideaprima.lt | O21: +370 5 2120317 | R21: 30 | S21: 26 | T21: -0.13333333 | U21: 31 | V21: 0.19230769 | W21: 37 | X21: 0.19354839 | Y21: 36 | Z21: -0.027027027 | AA21: 30 | AB21: -0.16666667 | AC21: 24 | AD21: 1979 | AE21: 2145 | AF21: 0.083880748 | AG21: 2734 | AH21: 0.27459207 | AI21: 2592 | AJ21: -0.051938552 | AK21: 2930 | AL21: 0.13040123 | AM21: 3374 | AN21: 0.15153584 | AO21: 4168,51 | AQ21: 2121009 | AR21: 2078484 | AS21: -0.02004942 | AT21: 2384972 | AU21: 0.14745747 | AV21: 2603242 | AW21: 0.091518894 | AX21: 3033004 | AY21: 0.16508723 | AZ21: 2912372 | BA21: -0.039773109 | BB21: 157012 | BC21: 195838 | BD21: 0.24728046 | BE21: 143615 | BF21: -0.26666428 | BG21: 172279 | BH21: 0.19958918 | BI21: 119309 | BJ21: -0.30746638 | BK21: 31793 | BL21: -0.73352387 | BM21: http://www.ideaprima.lt | BN21: https://rekvizitai.vz.lt/imone/idea_prima/ | BO21: https://www.facebook.com/kasnaujoposaule | BP21: https://www.instagram.com/idea.prima/ | BR21: Žemiausia | BS21: 2002-11-27
A22: INK Agency, UAB | B22: inkagency.lt | C22: 702100 | F22: PR | G22: Digital media | I22: 300122046 | J22: LT100001738313 | K22: UAB "INK agency" | L22: Paupio g. 50-136, LT-11341 Vilnius | M22: Vilnius | N22: info@inkagency.lt | O22: +370 5 2102060 | P22: 37069678913 | R22: 21 | S22: 19 | T22: -0.095238095 | U22: 30 | V22: 0.57894737 | W22: 23 | X22: -0.23333333 | Y22: 19 | Z22: -0.17391304 | AA22: 19 | AB22: 0 | AC22: 20 | AD22: 2641 | AE22: 2472 | AF22: -0.063990913 | AG22: 2653 | AH22: 0.073220065 | AI22: 3013 | AJ22: 0.13569544 | AK22: 3356 | AL22: 0.11384003 | AM22: 3590 | AN22: 0.069725864 | AO22: 3599,04 | AQ22: 1437630 | AR22: 1657585 | AS22: 0.15299834 | AT22: 2138268 | AU22: 0.28998996 | AV22: 2505905 | AW22: 0.17193214 | AX22: 2356412 | AY22: -0.059656292 | AZ22: 2822488 | BA22: 0.19779054 | BB22: 29499 | BC22: 182089 | BD22: 5.1727177 | BE22: 92031 | BF22: -0.49458232 | BG22: 169053 | BH22: 0.83691365 | BI22: 171879 | BJ22: 0.016716651 | BK22: 134463 | BL22: -0.21768802 | BM22: http://www.inkagency.lt | BN22: https://rekvizitai.vz.lt/imone/ink_agency/ | BO22: https://www.facebook.com/inkagency.lt | BR22: Žemiausia | BS22: 2005-06-09
A23: Astos dizainas, UAB | C23: 731100 | E23: Kūryba | I23: 123932858 | J23: LT239328515 | K23: Uždaroji akcinė bendrovė "ASTOS DIZAINAS" | L23: Maironio g. 11, Vilnius | M23: Vilnius | N23: hello@truth.lt | O23: +370 5 2124509 | P23: 37061914508 | Q23: +370 619 14508 | R23: 31 | S23: 27 | T23: -0.12903226 | U23: 27 | V23: 0 | W23: 26 | X23: -0.037037037 | Y23: 25 | Z23: -0.038461538 | AA23: 27 | AB23: 0.08 | AC23: 25 | AD23: 2507 | AE23: 2557 | AF23: 0.019944156 | AG23: 2648 | AH23: 0.03558858 | AI23: 2759 | AJ23: 0.041918429 | AK23: 3002 | AL23: 0.08807539 | AM23: 3258 | AN23: 0.085276482 | AO23: 3100,24 | AQ23: 3492270 | AR23: 2865990 | AS23: -0.17933321 | AT23: 2310000 | AU23: -0.19399579 | AV23: 2365263 | AW23: 0.023923377 | AX23: 3544704 | AY23: 0.4986511 | AZ23: 2697617 | BA23: -0.23897256 | BB23: 181900 | BC23: 215262 | BD23: 0.18340847 | BE23: 44571 | BF23: -0.79294534 | BG23: -8181 | BH23: -1.1835498 | BI23: 262086 | BJ23: 33.035937 | BK23: 6319 | BL23: -0.97588959 | BM23: http://truth.lt | BN23: https://rekvizitai.vz.lt/imone/astos_dizainas/ | BR23: Žemiausia | BS23: 1997-03-14
A24: Integrity PR, UAB | B24: integrity.lt | C24: 702100 | F24: PR | I24: 111688780 | J24: LT116887811 | K24: UAB "INTEGRITY PR" | L24: Šv. Ignoto g. 5, LT-01144 Vilnius | M24: Vilnius | N24: info@integrity.lt | O24: +370 5 2685135 | R24: 24 | S24: 25 | T24: 0.041666667 | U24: 25 | V24: 0 | W24: 26 | X24: 0.04 | Y24: 25 | Z24: -0.038461538 | AA24: 25 | AB24: 0 | AC24: 25 | AD24: 2463 | AE24: 2430 | AF24: -0.013398295 | AG24: 3043 | AH24: 0.25226337 | AI24: 2910 | AJ24: -0.043706868 | AK24: 3402 | AL24: 0.16907216 | AM24: 3253 | AN24: -0.043797766 | AO24: 3030,33 | AQ24: 1653501 | AR24: 1636617 | AS24: -0.010211061 | AT24: 2400631 | AU24: 0.46682516 | AV24: 2555494 | AW24: 0.064509289 | AX24: 2714172 | AY24: 0.062092887 | AZ24: 2679018 | BA24: -0.012952016 | BB24: 201395 | BC24: 198548 | BD24: -0.014136399 | BE24: 168857 | BF24: -0.14954067 | BG24: 240546 | BH24: 0.4245545 | BI24: 236314 | BJ24: -0.017593309 | BK24: 229286 | BL24: -0.029740092 | BM24: http://www.integrity.lt | BN24: https://rekvizitai.vz.lt/imone/integrity_pr/ | BO24: https://www.facebook.com/integritypr | BP24: https://www.instagram.com/integrity_pr/ | BQ24: https://www.linkedin.com/company/integrity-pr/ | BR24: Žemiausia | BS24: 2000-01-21
A25: Influenceriai.lt, UAB | B25: influenceriai.lt | C25: 731100 | D25: Reklamos agentūrų veikla | I25: 304747369 | J25: LT100011387310 | K25: UAB "Nuomonės lyderiai" | L25: Žygio g. 97A, LT-08236 Vilnius | M25: Vilnius | N25: hello@influenceriai.lt | P25: 37068038668 | R25: 3 | S25: 5 | T25: 0.66666667 | U25: 8 | V25: 0.6 | W25: 12 | X25: 0.5 | Y25: 12 | Z25: 0 | AA25: 13 | AB25: 0.083333333 | AC25: 12 | AD25: 1764 | AE25: 1914 | AF25: 0.085034014 | AG25: 2004 | AH25: 0.047021944 | AI25: 2143 | AJ25: 0.069361277 | AK25: 2169 | AL25: 0.012132524 | AM25: 2452 | AN25: 0.13047487 | AO25: 2688,34 | AQ25: 585857 | AR25: 1002530 | AS25: 0.71121963 | AT25: 1493124 | AU25: 0.48935593 | AV25: 1800902 | AW25: 0.20613023 | AX25: 1925562 | AY25: 0.069220868 | AZ25: 2454743 | BA25: 0.27481899 | BB25: 65878 | BC25: 82155 | BD25: 0.24707793 | BE25: 84513 | BF25: 0.028701844 | BG25: 25215 | BH25: -0.70164353 | BI25: 82666 | BJ25: 2.2784454 | BK25: 141326 | BL25: 0.7096025 | BM25: http://www.influenceriai.lt | BN25: https://rekvizitai.vz.lt/imone/nuomones_lyderiai/ | BO25: https://www.facebook.com/influenceriai.lt/ | BR25: Žemiausia | BS25: 2018-01-11
A26: Expertmedia, UAB | B26: expertmedia.lt | C26: 731100 | D26: Reklamos agentūrų veikla | I26: 301536032 | J26: LT100010428215 | K26: UAB "RAKVA" | L26: Šeškinės Sodų g. 12-51, Vilnius | M26: Vilnius | N26: zygimantas@expertmedia.lt | O26: +370 686 62078 | R26: 5 | S26: 9 | T26: 0.8 | U26: 11 | V26: 0.22222222 | W26: 13 | X26: 0.18181818 | Y26: 15 | Z26: 0.15384615 | AA26: 20 | AB26: 0.33333333 | AC26: 21 | AD26: 831 | AE26: 1019 | AF26: 0.22623345 | AG26: 1264 | AH26: 0.2404318 | AI26: 1660 | AJ26: 0.31329114 | AK26: 1792 | AL26: 0.079518072 | AM26: 2026 | AN26: 0.13058036 | AO26: 1966,87 | AQ26: 429578 | AR26: 433516 | AS26: 0.0091671361 | AT26: 727671 | AU26: 0.6785332 | AV26: 1065013 | AW26: 0.46359138 | AX26: 1326126 | AY26: 0.24517353 | AZ26: 1806257 | BA26: 0.36205534 | BB26: 176490 | BC26: 142713 | BD26: -0.19138195 | BE26: 263114 | BF26: 0.84365825 | BG26: 270828 | BH26: 0.02931809 | BI26: 264019 | BJ26: -0.025141418 | BK26: 354039 | BL26: 0.34096031 | BM26: http://www.expertmedia.lt | BN26: https://rekvizitai.vz.lt/imone/uab_rakva/ | BO26: https://www.facebook.com/expertmedia.lt | BP26: https://www.instagram.com/expertmedia.marketing/ | BQ26: https://www.linkedin.com/company/expertmedia-lietuva | BR26: Žema | BS26: 2008-02-04
A27: Sons & Daughters, UAB | C27: 731100 | E27: Kūryba | I27: 111621671 | J27: LT116216716 | K27: UAB "Sons & Daughters" | L27: J. Basanavičiaus g. 26, LT-03224 Vilnius | M27: Vilnius | N27: hi@sonsdaughters.lt | O27: +370 5 2312190 | R27: 15 | S27: 14 | T27: -0.066666667 | U27: 15 | V27: 0.071428571 | W27: 16 | X27: 0.066666667 | Y27: 18 | Z27: 0.125 | AA27: 18 | AB27: 0 | AC27: 17 | AD27: 2045 | AE27: 1657 | AF27: -0.18973105 | AG27: 2046 | AH27: 0.23476162 | AI27: 2269 | AJ27: 0.10899316 | AK27: 2874 | AL27: 0.26663729 | AM27: 3260 | AN27: 0.13430759 | AO27: 3384,45 | AQ27: 1489138 | AR27: 924221 | AS27: -0.37935839 | AT27: 641943 | AU27: -0.30542262 | AV27: 1895806 | AW27: 1.9532311 | AX27: 1885334 | AY27: -0.0055237719 | AZ27: 1795590 | BA27: -0.047601115 | BB27: 40764 | BC27: 31004 | BD27: -0.23942695 | BE27: -69609 | BF27: -3.2451619 | BG27: 39446 | BH27: 1.5666796 | BI27: 41716 | BJ27: 0.057547026 | BK27: 14732 | BL27: -0.64685013 | BM27: https://www.sonsdaughters.lt | BN27: https://rekvizitai.vz.lt/imone/ddb_vilnius/ | BO27: https://www.facebook.com/sons.daughters.agency | BR27: Žemiausia | BS27: 1998-02-19
A28: Headline, UAB | B28: headline.lt | C28: 702100 | F28: PR | I28: 301163601 | J28: LT100003575114 | K28: UAB "Headline Agency" | L28: Mėsinių g. 5, Vilnius | M28: Vilnius | N28: info@headline.lt | P28: 37068504820 | R28: 18 | S28: 15 | T28: -0.16666667 | U28: 13 | V28: -0.13333333 | W28: 15 | X28: 0.15384615 | Y28: 15 | Z28: 0 | AA28: 15 | AB28: 0 | AC28: 14 | AD28: 2233 | AE28: 2502 | AF28: 0.12046574 | AG28: 2615 | AH28: 0.045163869 | AI28: 2799 | AJ28: 0.070363289 | AK28: 3015 | AL28: 0.077170418 | AM28: 3176 | AN28: 0.053399668 | AO28: 3453,01 | AQ28: 1281358 | AR28: 1148506 | AS28: -0.10368063 | AT28: 1200820 | AU28: 0.04554961 | AV28: 1212715 | AW28: 0.0099057311 | AX28: 1844085 | AY28: 0.52062521 | AZ28: 1572640 | BA28: -0.14719766 | BB28: 183083 | BC28: 243883 | BD28: 0.33208982 | BE28: 160993 | BF28: -0.33987609 | BG28: 42675 | BH28: -0.73492636 | BI28: 208473 | BJ28: 3.8851318 | BK28: 45107 | BL28: -0.78363145 | BM28: http://www.headline.lt | BN28: https://rekvizitai.vz.lt/imone/headline_agency/ | BR28: Žemiausia | BS28: 2007-10-18
A29: Synthesis Consulting Group, UAB | B29: synthesis.lt | C29: 731100 | D29: Reklamos agentūrų veikla | I29: 304229686 | J29: LT100010176811 | K29: UAB "Synthesis Consulting Group" | L29: Raugyklos g. 21-2, Vilnius | M29: Vilnius | N29: gediminas@synthesiscg.com | Q29: +370 684 64083 | R29: 3 | S29: 4 | T29: 0.33333333 | U29: 4 | V29: 0 | W29: 5 | X29: 0.25 | Y29: 7 | Z29: 0.4 | AA29: 11 | AB29: 0.57142857 | AC29: 18 | AD29: \N | AE29: 1195 | AF29: \N | AG29: 1060 | AH29: -0.11297071 | AI29: 1269 | AJ29: 0.19716981 | AK29: 1899 | AL29: 0.4964539 | AM29: 2711 | AN29: 0.42759347 | AO29: 3199,51 | AQ29: 328025 | AR29: 451893 | AS29: 0.37761756 | AT29: 614560 | AU29: 0.35996796 | AV29: 766536 | AW29: 0.24729237 | AX29: 1054535 | AY29: 0.3757149 | AZ29: 1415385 | BA29: 0.34218874 | BB29: 107649 | BC29: 167397 | BD29: 0.55502606 | BE29: 293105 | BF29: 0.75095731 | BG29: 365575 | BH29: 0.24724928 | BI29: 486355 | BJ29: 0.33038364 | BK29: 518099 | BL29: 0.065269196 | BM29: https://synthesiscg.com/ | BN29: https://rekvizitai.vz.lt/imone/synthesis_consulting_group/ | BR29: Žemiausia | BS29: 2016-04-26
A30: We Are Marketing, UAB | B30: wearemarketing.lt | C30: 731100 | D30: Reklamos agentūrų veikla | I30: 302856900 | J30: LT100007131714 | K30: We Are Marketing, UAB | L30: Didžioji g. 30, LT-01128 Vilnius | M30: Vilnius | N30: hello@wearemarketing.lt | P30: 37062765286 | R30: 10 | S30: 10 | T30: 0 | U30: 17 | V30: 0.7 | W30: 21 | X30: 0.23529412 | Y30: 22 | Z30: 0.047619048 | AA30: 23 | AB30: 0.045454545 | AC30: 26 | AD30: 2052 | AE30: 2182 | AF30: 0.063352827 | AG30: 2301 | AH30: 0.054537122 | AI30: 2659 | AJ30: 0.15558453 | AK30: 2964 | AL30: 0.11470478 | AM30: 3336 | AN30: 0.12550607 | AO30: 4047,20 | AQ30: 338919 | AR30: 514461 | AS30: 0.51794677 | AT30: 747732 | AU30: 0.45342796 | AV30: 966637 | AW30: 0.29275864 | AX30: 1097125 | AY30: 0.13499173 | AZ30: 1247022 | BA30: 0.13662709 | BB30: -3515 | BC30: 92489 | BD30: 27.31266 | BE30: 44239 | BF30: -0.52168366 | BG30: -31125 | BH30: -1.7035647 | BI30: 9018 | BJ30: 1.2897349 | BK30: 111214 | BL30: 11.332446 | BM30: https://wearemarketing.lt | BN30: https://rekvizitai.vz.lt/imone/we_are_marketing_uab/ | BR30: Žemiausia | BS30: 2012-09-07
A31: Du Dvylika, UAB | C31: 731100 | E31: Kūryba | I31: 302535912 | J31: LT100005596915 | K31: UAB Du Dvylika | L31: J. Jasinskio g. 14B-102, Vilnius | M31: Vilnius | N31: jolanta@clinic212.lt | O31: +370 687 25465 | P31: 37069872889 | R31: 20 | S31: 18 | T31: -0.1 | U31: 19 | V31: 0.055555556 | W31: 22 | X31: 0.15789474 | Y31: 15 | Z31: -0.31818182 | AA31: 10 | AB31: -0.33333333 | AC31: 9 | AD31: 2654 | AE31: 2194 | AF31: -0.17332329 | AG31: 2888 | AH31: 0.31631723 | AI31: 2866 | AJ31: -0.0076177285 | AK31: 3251 | AL31: 0.13433357 | AM31: 3475 | AN31: 0.068901876 | AO31: 3781,30 | AQ31: 1758089 | AR31: 981515 | AS31: -0.44171484 | AT31: 1573797 | AU31: 0.60343652 | AV31: 1401240 | AW31: -0.10964375 | AX31: 1023984 | AY31: -0.26923011 | AZ31: 970809 | BA31: -0.051929522 | BB31: 2568 | BC31: -60714 | BD31: -24.642523 | BE31: 89068 | BF31: 2.4670093 | BG31: 44835 | BH31: -0.49662056 | BI31: -237451 | BJ31: -6.296108 | BK31: 45410 | BL31: 1.1912395 | BM31: http://www.clinic212.lt | BN31: https://rekvizitai.vz.lt/imone/uab_du_dvylika/ | BR31: Vidutinė | BS31: 2010-08-11
A32: Be reklamos negerai, UAB | B32: bereklamosnegerai.lt | C32: 731100 | D32: Reklamos agentūrų veikla | I32: 304933014 | J32: LT100011997316 | K32: UAB "Ateities rinkodara" | L32: Latvių g. 15, 1 aukštas, LT-08123 Vilnius | M32: Vilnius | N32: info@bereklamosnegerai.lt | P32: 37062177711 | R32: 2 | S32: 2 | T32: 0 | U32: 8 | V32: 3 | W32: 15 | X32: 0.875 | Y32: 15 | Z32: 0 | AA32: 18 | AB32: 0.2 | AC32: 17 | AD32: \N | AE32: \N | AF32: \N | AG32: 1201 | AH32: \N | AI32: 1353 | AJ32: 0.1265612 | AK32: 1957 | AL32: 0.44641537 | AM32: 2075 | AN32: 0.060296372 | AO32: 2326,87 | AQ32: 52181 | AR32: 120421 | AS32: 1.3077557 | AT32: 470300 | AU32: 2.905465 | AV32: 733653 | AW32: 0.55996811 | AX32: 999514 | AY32: 0.36237976 | AZ32: 853822 | BA32: -0.14576284 | BB32: -6006 | BC32: 44975 | BD32: 8.488345 | BE32: 47893 | BF32: 0.064880489 | BG32: 27646 | BH32: -0.42275489 | BI32: -18442 | BJ32: -1.6670766 | BK32: -94467 | BL32: -4.1223837 | BM32: http://www.bereklamosnegerai.lt/ | BN32: https://rekvizitai.vz.lt/imone/ateities_rinkodara/ | BO32: https://www.facebook.com/bereklamosnegerai.lt/ | BP32: https://www.instagram.com/be_reklamos_negerai/ | BQ32: https://www.linkedin.com/company/be-reklamos-negerai | BR32: Aukšta | BS32: 2018-10-12
A33: RAIBEC, UAB | B33: raibec.lt | C33: 620100 | D33: Kompiuterių programavimo veikla | I33: 148508931 | J33: LT485089314 | K33: UAB "LITS" | L33: Nemuno g. 76-34, LT-35190 Panevėžys | M33: Panevėžys | N33: info@lits.lt | P33: 37063000933 | R33: 8 | S33: 8 | T33: 0 | U33: 5 | V33: -0.375 | W33: 5 | X33: 0 | Y33: 7 | Z33: 0.4 | AA33: 7 | AB33: 0 | AC33: 9 | AD33: 1445 | AE33: 1860 | AF33: 0.28719723 | AG33: 2168 | AH33: 0.1655914 | AI33: 2786 | AJ33: 0.28505535 | AK33: 2400 | AL33: -0.13854989 | AM33: 2948 | AN33: 0.22833333 | AO33: 3364,73 | AQ33: 388517 | AR33: 481436 | AS33: 0.23916328 | AT33: 545455 | AU33: 0.1329751 | AV33: 555622 | AW33: 0.018639484 | AX33: 539977 | AY33: -0.028157632 | AZ33: 843249 | BA33: 0.56163874 | BB33: -35923 | BC33: -31585 | BD33: 0.12075829 | BE33: 47420 | BF33: 2.5013456 | BG33: -7750 | BH33: -1.1634332 | BI33: 3530 | BJ33: 1.4554839 | BK33: 2897 | BL33: -0.17932011 | BM33: https://www.lits.lt | BN33: https://rekvizitai.vz.lt/imone/raibec_be_efficient_online/ | BR33: Žemiausia | BS33: 2003-01-22
A34: Smart, UAB | B34: smarts.lt | C34: 731100 | D34: Reklamos agentūrų veikla | I34: 126327871 | J34: LT263278716 | K34: UAB "Protingi sprendimai" | L34: Kęstučio g. 65-201, Vilnius | M34: Vilnius | N34: info@smarts.lt | O34: +370 5 2313933 | R34: 17 | S34: 15 | T34: -0.11764706 | U34: 15 | V34: 0 | W34: 15 | X34: 0 | Y34: 14 | Z34: -0.066666667 | AA34: 15 | AB34: 0.071428571 | AC34: 15 | AD34: 1300 | AE34: 1249 | AF34: -0.039230769 | AG34: 1588 | AH34: 0.27141713 | AI34: 1795 | AJ34: 0.13035264 | AK34: 1791 | AL34: -0.0022284123 | AM34: 1938 | AN34: 0.082077052 | AO34: 2209,90 | AQ34: 595599 | AR34: 561515 | AS34: -0.057226422 | AT34: 762011 | AU34: 0.35706259 | AV34: 838212 | AW34: 0.099999869 | AX34: 769072 | AY34: -0.082485099 | AZ34: 835662 | BA34: 0.086584871 | BB34: 35717 | BC34: 103404 | BD34: 1.895092 | BE34: 77632 | BF34: -0.24923601 | BG34: 83201 | BH34: 0.071735882 | BI34: 67259 | BJ34: -0.19160827 | BK34: 54979 | BL34: -0.1825778 | BM34: http://www.smarts.lt | BN34: https://rekvizitai.vz.lt/imone/protingi_sprendimai/ | BR34: Žemiausia | BS34: 2003-09-22
A35: Nomads, UAB | B35: nomads.lt | C35: 721100 | D35: Biotechnologijos moksliniai tyrimai ir taikomoji veikla | I35: 302441263 | J35: LT100005225412 | K35: UAB "Nomads" | L35: Mokslininkų g. 2, Vilnius | M35: Vilnius | N35: \N | O35: +370 5 2331589 | P35: 37067965278 | R35: 11 | S35: 11 | T35: 0 | U35: 11 | V35: 0 | W35: 11 | X35: 0 | Y35: 11 | Z35: 0 | AA35: 7 | AB35: -0.36363636 | AC35: 2 | AD35: 3769 | AE35: 2903 | AF35: -0.22976917 | AG35: 2960 | AH35: 0.01963486 | AI35: 3094 | AJ35: 0.04527027 | AK35: 3041 | AL35: -0.017129929 | AM35: 2976 | AN35: -0.021374548 | AO35: \N | AQ35: 370000 | AR35: 370012 | AS35: 3.2432432e-05 | AT35: 370306 | AU35: 0.00079456882 | AV35: 370010 | AW35: -0.00079933893 | AX35: 403000 | AY35: 0.089159752 | AZ35: 675612 | BA35: 0.67645658 | BB35: 3481 | BC35: 39130 | BD35: 10.241023 | BE35: 27424 | BF35: -0.29915666 | BG35: -117809 | BH35: -5.2958358 | BI35: -220748 | BJ35: -0.87377874 | BK35: 146126 | BL35: 1.6619584 | BN35: https://rekvizitai.vz.lt/imone/uab_nomads/ | BR35: Žemiausia | BS35: 2009-09-28
A36: Maniac, UAB | B36: maniac.lt | C36: 702200 | F36: PR | I36: 110889086 | J36: LT108890811 | K36: UAB "Maniakai" | L36: J. Jasinskio g. 16A, LT-03163 Vilnius | M36: Vilnius | N36: maniac@maniac.lt | O36: +370 5 2791747 | R36: 7 | S36: 8 | T36: 0.14285714 | U36: 7 | V36: -0.125 | W36: 7 | X36: 0 | Y36: 6 | Z36: -0.14285714 | AA36: 6 | AB36: 0 | AC36: 6 | AD36: 1994 | AE36: 1582 | AF36: -0.20661986 | AG36: 1820 | AH36: 0.15044248 | AI36: 1975 | AJ36: 0.085164835 | AK36: 2056 | AL36: 0.041012658 | AM36: 1935 | AN36: -0.05885214 | AO36: 1593,45 | AQ36: 517914 | AR36: 544393 | AS36: 0.051126249 | AT36: 670268 | AU36: 0.23122083 | AV36: 645477 | AW36: -0.036986698 | AX36: 640668 | AY36: -0.0074503042 | AZ36: 645283 | BA36: 0.0072034189 | BB36: 129879 | BC36: 128289 | BD36: -0.012242164 | BE36: 216103 | BF36: 0.6845014 | BG36: 195790 | BH36: -0.093996844 | BI36: 219317 | BJ36: 0.12016446 | BK36: 222567 | BL36: 0.014818733 | BM36: http://www.maniac.lt | BN36: https://rekvizitai.vz.lt/imone/maniakai/ | BR36: Žemiausia | BS36: 2003-04-17
A37: Convo, UAB | B37: convo.lt | C37: 731100 | D37: Reklamos agentūrų veikla | I37: 304754709 | J37: LT100011432219 | K37: UAB "Sėkmingi" | L37: Putvinskio g. 62, LT-44211 Kaunas | M37: Kaunas | N37: hello@convo.lt | O37: +370 687 73251 | R37: 4 | S37: 6 | T37: 0.5 | U37: 8 | V37: 0.33333333 | W37: 10 | X37: 0.25 | Y37: 12 | Z37: 0.2 | AA37: 12 | AB37: 0 | AC37: 13 | AD37: 825 | AE37: 915 | AF37: 0.10909091 | AG37: 1144 | AH37: 0.25027322 | AI37: 1415 | AJ37: 0.23688811 | AK37: 1933 | AL37: 0.36607774 | AM37: 2028 | AN37: 0.049146405 | AO37: 2024,81 | AQ37: 76508 | AR37: 111249 | AS37: 0.45408323 | AT37: 205766 | AU37: 0.84959865 | AV37: 370276 | AW37: 0.7995004 | AX37: 534736 | AY37: 0.44415517 | AZ37: 514040 | BA37: -0.038703211 | BB37: -2709 | BC37: 0 | BD37: 1 | BE37: 2662 | BF37: \N | BG37: 13356 | BH37: 4.0172802 | BI37: 51317 | BJ37: 2.8422432 | BK37: 17322 | BL37: -0.66245104 | BM37: http://www.convo.lt | BN37: https://rekvizitai.vz.lt/imone/sekmingi/ | BO37: https://www.facebook.com/agencyconvo | BQ37: https://www.linkedin.com/company/agencyconvo | BR37: Žemiausia | BS37: 2018-01-26
A38: Particle PR, UAB | B38: particlepr.lt | C38: 702100 | F38: PR | I38: 306313364 | J38: LT100016237315 | K38: UAB Particle PR | L38: Raugyklos g. 21-15, Vilnius | M38: Vilnius | N38: kskindelyte@gmail.com | P38: 37060063171 | R38: \N | S38: \N | T38: \N | U38: \N | V38: \N | W38: \N | X38: \N | Y38: 5 | Z38: \N | AA38: 6 | AB38: 0.2 | AC38: 7 | AD38: \N | AE38: \N | AF38: \N | AG38: \N | AH38: \N | AI38: \N | AJ38: \N | AK38: 2871 | AL38: \N | AM38: 2938 | AN38: 0.023336816 | AO38: 3042,61 | AS38: \N | AU38: \N | AW38: \N | AX38: 133678 | AY38: \N | AZ38: 474855 | BA38: 2.55223 | BD38: \N | BF38: \N | BH38: \N | BI38: 30861 | BJ38: \N | BK38: 74154 | BL38: 1.4028385 | BN38: https://rekvizitai.vz.lt/imone/perception_lab/ | BR38: Žemiausia | BS38: 2023-05-09
A39: Panama Agency, UAB | B39: panamaagency.lt | C39: 731100 | F39: PR | I39: 305678883 | J39: LT100013724319 | K39: MB Panama agency | L39: Liepų g. 83, LT-92195 Klaipėda | M39: Klaipėda | N39: info@agencypanama.lt | P39: 37064119828 | R39: \N | S39: \N | T39: \N | U39: 1 | V39: \N | W39: 2 | X39: 1 | Y39: 3 | Z39: 0.5 | AA39: 5 | AB39: 0.66666667 | AC39: 8 | AD39: \N | AE39: \N | AF39: \N | AG39: \N | AH39: \N | AI39: \N | AJ39: \N | AK39: 1420 | AL39: \N | AM39: 1995 | AN39: 0.40492958 | AO39: 2159,38 | AS39: \N | AT39: 71239 | AU39: \N | AV39: 187499 | AW39: 1.6319713 | AX39: 239698 | AY39: 0.27839615 | AZ39: 407865 | BA39: 0.70157865 | BD39: \N | BE39: 8688 | BF39: \N | BG39: 36059 | BH39: 3.1504374 | BI39: 12907 | BJ39: -0.64205885 | BK39: 60868 | BL39: 3.7158906 | BM39: http://agencypanama.lt | BN39: https://rekvizitai.vz.lt/imone/panama_agency/ | BO39: https://www.facebook.com/agencypanama | BP39: https://www.instagram.com/agencypanama.lt | BQ39: https://www.linkedin.com/company/agencypanama | BR39: Žemiausia | BS39: 2021-01-11
A40: IC Baltic, UAB | C40: 702100 | D40: Viešųjų ryšių ir komunikacijos veikla | I40: 300016915 | J40: LT100000966518 | K40: UAB "IC BALTIC" | L40: Manufaktūrų g. 20-232, LT-11342 Vilnius | M40: Vilnius | N40: office@impactadvisory.eu | P40: 37061526019 | R40: 5 | S40: 3 | T40: -0.4 | U40: 4 | V40: 0.33333333 | W40: 5 | X40: 0.25 | Y40: 6 | Z40: 0.2 | AA40: 3 | AB40: -0.5 | AC40: 1 | AD40: 1572 | AE40: 2349 | AF40: 0.49427481 | AG40: 2364 | AH40: 0.006385696 | AI40: 1821 | AJ40: -0.22969543 | AK40: 2005 | AL40: 0.10104338 | AM40: 2055 | AN40: 0.024937656 | AO40: \N | AQ40: 135593 | AR40: 140132 | AS40: 0.033475179 | AT40: 204229 | AU40: 0.45740445 | AV40: 308709 | AW40: 0.51158259 | AX40: 463961 | AY40: 0.50290727 | AZ40: 339411 | BA40: -0.26844929 | BB40: 12672 | BC40: 733 | BD40: -0.94215593 | BE40: 5655 | BF40: 6.7148704 | BG40: -48 | BH40: -1.0084881 | BI40: 1304 | BJ40: 28.166667 | BK40: 789 | BL40: -0.39493865 | BM40: https://www.impactadvisory.eu | BN40: https://rekvizitai.vz.lt/imone/ic_baltic/ | BR40: Žemiausia | BS40: 2004-04-09
...

Sheet Įmonės
A1: Pavadinimas | B1: Pagrindinis brandas | C1: Svetainė | D1: EVRK v2 veiklos kodas | E1: EVRK v2 veikla | F1: Veikla (kūryba) | G1: Veikla (PR) | H1: Veikla (Digital media) | I1: Veikla (PA) | J1: Kodas | K1: PVM kodas | L1: Įmonė | M1: Adresas | N1: Miestas | O1: El. paštas | P1: Telefonas | Q1: Mobilus | R1: Darbuotojai 2019 | S1: Darbuotojai 2020 | T1: Darb. Pokytis 19-20 | U1: Darbuotojai 2021 | V1: Darb. Pokytis 20-21 | W1: Darbuotojai 2022 | X1: Darb. Pokytis 21-22 | Y1: Darbuotojai 2023 | Z1: Darb. Pokytis 22-23 | AA1: Darbuotojai 2024 | AB1: Darb. Pokytis 23-24 | AC1: Darbuotojai 2025 06 09 | AD1: Atlyginimų vidurkis 2019 | AE1: Atlyginimų sąnaudos 2019 | AF1: Ne atlyginimų sąnaudos darbuotojui 2019 | AG1: Atlyginimų vidurkis 2020 | AH1: Atlyginimų sąnaudos 2020 | AI1: Ne atlyginimų sąnaudos darbuotojui 2020 | AJ1: Atl .Pokytis 19-20 | AK1: Atlyginimų vidurkis 2021 | AL1: Atlyginimų sąnaudos 2021 | AM1: Ne atlyginimų sąnaudos darbuotojui 2021 | AN1: Atl. Pokytis 20-21 | AO1: Atlyginimų vidurkis 2022 | AP1: Atlyginimų sąnaudos 2022 | AQ1: Ne atlyginimų sąnaudos darbuotojui 2022 | AR1: Atl. Pokytis 21-22 | AS1: Atlyginimų vidurkis 2023 | AT1: Atlyginimų sąnaudos 2023 | AU1: Ne atlyginimų sąnaudos darbuotojui 2023 | AV1: Atl. Pokytis 22-23 | AW1: Atlyginimų vidurkis 2024 | AX1: Atlyginimų sąnaudos 2024 | AY1: Ne atlyginimų sąnaudos darbuotojui 2024 | AZ1: Atl. Pokytis 23-24 | BA1: Atlyginimų vidurkis 2025 04 | BB1: Atlyginimų sąnaudos 2025 05 | BC1: Skola Sodrai | BD1: Apyvarta 2019 | BE1: Apyvarta 2020 | BF1: Apyvart. Pokytis 19-20 | BG1: Apyvarta 2021 | BH1: Apyvart. Pokytis 20-21 | BI1: Apyvarta 2022 | BJ1: Apyvart. Pokytis 21-22 | BK1: Apyvarta 2023 | BL1: Apyvart. Pokytis 22-23 | BM1: Apyvarta 2024 | BN1: Apyvart. Pokytis 23-24 | BO1: Grynasis pelnas 2019 | BP1: Grynasis pelnas 2020 | BQ1: Gr. Peln. Pokytis 19-20 | BR1: Grynasis pelnas 2021 | BS1: Gr. Peln. Pokytis 20-21 | BT1: Grynasis pelnas 2022 | BU1: Gr. Peln. Pokytis 21-22 | BV1: Grynasis pelnas 2023 | BW1: Gr. Peln. Pokytis 22-23 | BX1: Grynasis pelnas 2024 | BY1: Gr. Peln. Pokytis 23-24 | BZ1: Rekvizitai URL | CA1: Facebook | CB1: Instagram | CC1: LinkedIn | CD1: Kredito rizika | CE1: Įregistruota
A2: 6 Loops, UAB | B2: 6 Loops | C2: 6loops.lt | D2: 731100 | E2: Reklamos agentūrų veikla | J2: 304405052 | L2: 6 vijos, MB | M2: Polocko g. 51-11, LT-01205 Vilnius | N2: Vilnius | O2: info@6loops.lt | Q2: 37065097123 | R2: \N | S2: \N | T2: \N | U2: \N | V2: \N | W2: \N | X2: \N | Y2: \N | Z2: \N | AA2: 1 | AB2: \N | AC2: 1 | AD2: \N | AE2: \N | AF2: \N | AG2: \N | AH2: \N | AI2: \N | AJ2: \N | AK2: \N | AL2: \N | AM2: \N | AN2: \N | AO2: \N | AP2: \N | AQ2: \N | AR2: \N | AS2: \N | AT2: \N | AU2: \N | AV2: \N | AW2: \N | AX2: \N | AY2: \N | AZ2: \N | BA2: \N | BB2: \N | BD2: 3060 | BE2: 4301 | BF2: 0.40555556 | BH2: \N | BI2: 0 | BJ2: \N | BK2: 23740 | BL2: \N | BM2: 60840 | BN2: 1.5627633 | BO2: -3087 | BP2: 1 | BQ2: 1.0003239 | BR2: 0 | BS2: -1 | BT2: 0 | BU2: 0 | BV2: 18605 | BW2: \N | BX2: 31289 | BY2: 0.68175222 | BZ2: https://rekvizitai.vz.lt/imone/6_vijos/ | CC2: https://www.linkedin.com/company/6-loops/ | CD2: Žemiausia | CE2: 2016-09-28
A3: Adell reklama, UAB | B3: Ogilvy | C3: ogilvy.lt | D3: 731100 | F3: Kūryba | J3: 110771682 | K3: LT107716811 | L3: ADELL REKLAMA, UAB | M3: Aukštaičių g. 7u, LT-11341 Vilnius | N3: Vilnius | O3: david@ogilvy.lt | P3: +370 619 19525 | R3: 45 | S3: 46 | T3: 0.022222222 | U3: 50 | V3: 0.086956522 | W3: 49 | X3: -0.02 | Y3: 49 | Z3: 0 | AA3: 45 | AB3: -0.081632653 | AC3: 43 | AD3: 2709 | AE3: =_20250609_reklama_data[[#This Row],[Atlyginimų vidurkis 2019]]*_20250609_reklama_data[[#This Row],[Darbuotojai 2019]]*12 -> 1462860 | AF3: =(_20250609_reklama_data[[#This Row],[Apyvarta 2019]]-_20250609_reklama_data[[#This Row],[Atlyginimų sąnaudos 2019]])/_20250609_reklama_data[[#This Row],[Darbuotojai 2019]] -> 129503.11 | AG3: 2940 | AH3: =_20250609_reklama_data[[#This Row],[Atlyginimų vidurkis 2020]]*_20250609_reklama_data[[#This Row],[Darbuotojai 2020]]*12 -> 1622880 | AI3: =(_20250609_reklama_data[[#This Row],[Apyvarta 2020]]-_20250609_reklama_data[[#This Row],[Atlyginimų sąnaudos 2020]])/_20250609_reklama_data[[#This Row],[Darbuotojai 2020]] -> 107200.65 | AJ3: 0.085271318 | AK3: 3106 | AL3: =_20250609_reklama_data[[#This Row],[Atlyginimų vidurkis 2021]]*_20250609_reklama_data[[#This Row],[Darbuotojai 2021]]*12 -> 1863600 | AM3: =(_20250609_reklama_data[[#This Row],[Apyvarta 2021]]-_20250609_reklama_data[[#This Row],[Atlyginimų sąnaudos 2021]])/_20250609_reklama_data[[#This Row],[Darbuotojai 2021]] -> 102944.94 | AN3: 0.056462585 | AO3: 3263 | AP3: =_20250609_reklama_data[[#This Row],[Atlyginimų vidurkis 2022]]*_20250609_reklama_data[[#This Row],[Darbuotojai 2022]]*12 -> 1918644 | AQ3: =(_20250609_reklama_data[[#This Row],[Apyvarta 2022]]-_20250609_reklama_data[[#This Row],[Atlyginimų sąnaudos 2022]])/_20250609_reklama_data[[#This Row],[Darbuotojai 2022]] -> 133005.24 | AR3: 0.050547328 | AS3: 4041 | AT3: =_20250609_reklama_data[[#This Row],[Atlyginimų vidurkis 2023]]*_20250609_reklama_data[[#This Row],[Darbuotojai 2023]]*12 -> 2376108 | AU3: =(_20250609_reklama_data[[#This Row],[Apyvarta 2023]]-_20250609_reklama_data[[#This Row],[Atlyginimų sąnaudos 2023]])/_20250609_reklama_data[[#This Row],[Darbuotojai 2023]] -> 107863.49 | AV3: 0.23843089 | AW3: 3618 | AX3: =_20250609_reklama_data[[#This Row],[Atlyginimų vidurkis 2024]]*_20250609_reklama_data[[#This Row],[Darbuotojai 2024]]*12 -> 1953720 | AY3: =(_20250609_reklama_data[[#This Row],[Apyvarta 2024]]-_20250609_reklama_data[[#This Row],[Atlyginimų sąnaudos 2024]])/_20250609_reklama_data[[#This Row],[Darbuotojai 2024]] -> 122292.42 | AZ3: -0.10467706 | BA3: 3183,97 | BB3: =_20250609_reklama_data[[#This Row],[Atlyginimų vidurkis 2025 04]]*_20250609_reklama_data[[#This Row],[Darbuotojai 2025 06 09]]*5 -> 684553.55 | BD3: 7290500 | BE3: 6554110 | BF3: -0.10100679 | BG3: 7010847 | BH3: 0.069687112 | BI3: 8435901 | BJ3: 0.20326417 | BK3: 7661419 | BL3: -0.091807858 | BM3: 7456879 | BN3: -0.026697404 | BO3: 638469 | BP3: 637044 | BQ3: -0.0022319016 | BR3: 689700 | BS3: 0.082656771 | BT3: 1148871 | BU3: 0.66575468 | BV3: 625927 | BW3: -0.45518078 | BX3: 493389 | BY3: -0.21174674 | BZ3: https://rekvizitai.vz.lt/imone/adell_reklama/ | CA3: https://www.facebook.com/OgilvyVilnius | CB3: https://www.instagram.com/ogilvy_vilnius/ | CC3: https://www.linkedin.com/company/ogilvy-vilnius/ | CD3: Žemiausia | CE3: 1997-04-18
A4: Adface, UAB | B4: Adface | C4: adface.lt | D4: 731100 | F4: Kūryba | J4: 301734377 | K4: LT100004124412 | L4: Adface, UAB | M4: Vilties g. 2, LT-46326 Kaunas | N4: Kaunas | O4: info@adface.lt | Q4: 37060781646 | R4: 4 | S4: 4 | T4: 0 | U4: 5 | V4: 0.25 | W4: 6 | X4: 0.2 | Y4: 9 | Z4: 0.5 | AA4: 9 | AB4: 0 | AC4: 7 | AD4: 1065 | AE4: =_20250609_reklama_data[[#This Row],[Atlyginimų vidurkis 2019]]*_20250609_reklama_data[[#This Row],[Darbuotojai 2019]]*12 -> 51120 | AF4: =(_20250609_reklama_data[[#This Row],[Apyvarta 2019]]-_20250609_reklama_data[[#This Row],[Atlyginimų sąnaudos 2019]])/_20250609_reklama_data[[#This Row],[Darbuotojai 2019]] -> 13124 | AG4: 1170 | AH4: =_20250609_reklama_data[[#This Row],[Atlyginimų vidurkis 2020]]*_20250609_reklama_data[[#This Row],[Darbuotojai 2020]]*12 -> 56160 | AI4: =(_20250609_reklama_data[[#This Row],[Apyvarta 2020]]-_20250609_reklama_data[[#This Row],[Atlyginimų sąnaudos 2020]])/_20250609_reklama_data[[#This Row],[Darbuotojai 2020]] -> 13669.75 | AJ4: 0.098591549 | AK4: 1308 | AL4: =_20250609_reklama_data[[#This Row],[Atlyginimų vidurkis 2021]]*_20250609_reklama_data[[#This Row],[Darbuotojai 2021]]*12 -> 78480 | AM4: =(_20250609_reklama_data[[#This Row],[Apyvarta 2021]]-_20250609_reklama_data[[#This Row],[Atlyginimų sąnaudos 2021]])/_20250609_reklama_data[[#This Row],[Darbuotojai 2021]] -> 16834.8 | AN4: 0.11794872 | AO4: 1500 | AP4: =_20250609_reklama_data[[#This Row],[Atlyginimų vidurkis 2022]]*_20250609_reklama_data[[#This Row],[Darbuotojai 2022]]*12 -> 108000 | AQ4: =(_20250609_reklama_data[[#This Row],[Apyvarta 2022]]-_20250609_reklama_data[[#This Row],[Atlyginimų sąnaudos 2022]])/_20250609_reklama_data[[#This Row],[Darbuotojai 2022]] -> 11207.5 | AR4: 0.14678899 | AS4: 1529 | AT4: =_20250609_reklama_data[[#This Row],[Atlyginimų vidurkis 2023]]*_20250609_reklama_data[[#This Row],[Darbuotojai 2023]]*12 -> 165132 | AU4: =(_20250609_reklama_data[[#This Row],[Apyvarta 2023]]-_20250609_reklama_data[[#This Row],[Atlyginimų sąnaudos 2023]])/_20250609_reklama_data[[#This Row],[Darbuotojai 2023]] -> 7606.8889 | AV4: 0.019333333 | AW4: 1848 | AX4: =_20250609_reklama_data[[#This Row],[Atlyginimų vidurkis 2024]]*_20250609_reklama_data[[#This Row],[Darbuotojai 2024]]*12 -> 199584 | AY4: =(_20250609_reklama_data[[#This Row],[Apyvarta 2024]]-_20250609_reklama_data[[#This Row],[Atlyginimų sąnaudos 2024]])/_20250609_reklama_data[[#This Row],[Darbuotojai 2024]] -> 1450.5556 | AZ4: 0.20863309 | BA4: 1928,05 | BB4: =_20250609_reklama_data[[#This Row],[Atlyginimų vidurkis 2025 04]]*_20250609_reklama_data[[#This Row],[Darbuotojai 2025 06 09]]*5 -> 67481.75 | BD4: 103616 | BE4: 110839 | BF4: 0.069709311 | BG4: 162654 | BH4: 0.46747986 | BI4: 175245 | BJ4: 0.077409716 | BK4: 233594 | BL4: 0.33295672 | BM4: 212639 | BN4: -0.089706927 | BO4: 1139 | BP4: 8918 | BQ4: 6.8296752 | BR4: 37970 | BS4: 3.2576811 | BT4: 34783 | BU4: -0.083934685 | BV4: 19870 | BW4: -0.42874393 | BX4: 4687 | BY4: -0.76411676 | BZ4: https://rekvizitai.vz.lt/imone/adface/ | CA4: https://www.facebook.com/marketingoagenturaADFACE | CC4: https://www.linkedin.com/company/adface-agency | CD4: Žema | CE4: 2008-05-27
A5: Adverum, UAB | B5: Adverum | C5: adverum.lt | D5: 702100 | G5: PR | J5: 300003647 | K5: LT140489219 | L5: ADVERUM, UAB | M5: Gedimino pr. 27, LT-01104 Vilnius | N5: Vilnius | O5: hello@adverum.lt | P5: +370 5 2336561 | Q5: 37065500448 | R5: 11 | S5: 12 | T5: 0.090909091 | U5: 13 | V5: 0.083333333 | W5: 14 | X5: 0.076923077 | Y5: 13 | Z5: -0.071428571 | AA5: 12 | AB5: -0.076923077 | AC5: 13 | AD5: 1861 | AE5: =_20250609_reklama_data[[#This Row],[Atlyginimų vidurkis 2019]]*_20250609_reklama_data[[#This Row],[Darbuotojai 2019]]*12 -> 245652 | AF5: =(_20250609_reklama_data[[#This Row],[Apyvarta 2019]]-_20250609_reklama_data[[#This Row],[Atlyginimų sąnaudos 2019]])/_20250609_reklama_data[[#This Row],[Darbuotojai 2019]] -> 38353.091 | AG5: 2035 | AH5: =_20250609_reklama_data[[#This Row],[Atlyginimų vidurkis 2020]]*_20250609_reklama_data[[#This Row],[Darbuotojai 2020]]*12 -> 293040 | AI5: =(_20250609_reklama_data[[#This Row],[Apyvarta 2020]]-_20250609_reklama_data[[#This Row],[Atlyginimų sąnaudos 2020]])/_20250609_reklama_data[[#This Row],[Darbuotojai 2020]] -> 37628.583 | AJ5: 0.093498119 | AK5: 2318 | AL5: =_20250609_reklama_data[[#This Row],[Atlyginimų vidurkis 2021]]*_20250609_reklama_data[[#This Row],[Darbuotojai 2021]]*12 -> 361608 | AM5: =(_20250609_reklama_data[[#This Row],[Apyvarta 2021]]-_20250609_reklama_data[[#This Row],[Atlyginimų sąnaudos 2021]])/_20250609_reklama_data[[#This Row],[Darbuotojai 2021]] -> 85125.462 | AN5: 0.13906634 | AO5: 2323 | AP5: =_20250609_reklama_data[[#This Row],[Atlyginimų vidurkis 2022]]*_20250609_reklama_data[[#This Row],[Darbuotojai 2022]]*12 -> 390264 | AQ5: =(_20250609_reklama_data[[#This Row],[Apyvarta 2022]]-_20250609_reklama_data[[#This Row],[Atlyginimų sąnaudos 2022]])/_20250609_reklama_data[[#This Row],[Darbuotojai 2022]] -> 61512.571 | AR5: 0.0021570319 | AS5: 2442 | AT5: =_20250609_reklama_data[[#This Row],[Atlyginimų vidurkis 2023]]*_20250609_reklama_data[[#This Row],[Darbuotojai 2023]]*12 -> 380952 | AU5: =(_20250609_reklama_data[[#This Row],[Apyvarta 2023]]-_20250609_reklama_data[[#This Row],[Atlyginimų sąnaudos 2023]])/_20250609_reklama_data[[#This Row],[Darbuotojai 2023]] -> 86465.231 | AV5: 0.051226862 | AW5: 2597 | AX5: =_20250609_reklama_data[[#This Row],[Atlyginimų vidurkis 2024]]*_20250609_reklama_data[[#This Row],[Darbuotojai 2024]]*12 -> 373968 | AY5: =(_20250609_reklama_data[[#This Row],[Apyvarta 2024]]-_20250609_reklama_data[[#This Row],[Atlyginimų sąnaudos 2024]])/_20250609_reklama_data[[#This Row],[Darbuotojai 2024]] -> -31164 | AZ5: 0.063472563 | BA5: 2834,95 | BB5: =_20250609_reklama_data[[#This Row],[Atlyginimų vidurkis 2025 04]]*_20250609_reklama_data[[#This Row],[Darbuotojai 2025 06 09]]*5 -> 184271.75 | BD5: 667536 | BE5: 744583 | BF5: 0.11541999 | BG5: 1468239 | BH5: 0.97189434 | BI5: 1251440 | BJ5: -0.1476592 | BK5: 1505000 | BL5: 0.20261459 | BN5: \N | BO5: 62597 | BP5: 46689 | BQ5: -0.25413358 | BR5: 259227 | BS5: 4.5522072 | BT5: 201023 | BU5: -0.22452908 | BV5: 318511 | BW5: 0.58445054 | BY5: \N | BZ5: https://rekvizitai.vz.lt/imone/ad_verum/ | CA5: https://www.facebook.com/adverum | CB5: https://www.instagram.com/adverum.lt/ | CC5: https://www.linkedin.com/company/ad-verum | CD5: Žemiausia | CE5: 2004-02-17
